<?xml version="1.0" encoding="UTF-8"?>
<!-- Generated by org.testng.reporters.JUnitReportReporter -->
<testsuite name="AlertAware.api.test.SignIn" tests="4" time="2.891" ignored="4" failures="1" timestamp="12 May 2021 20:22:50 GMT" skipped="0" hostname="YASUs-MBP" errors="0">
  <testcase name="loginAsAUserWithValidCredentials" time="2.345" classname="AlertAware.api.test.SignIn"/>
  <testcase name="logoutCurrentUser" time="0.268" classname="AlertAware.api.test.SignIn">
    <failure type="java.lang.AssertionError" message="expected [200] but found [400]">
      <![CDATA[java.lang.AssertionError: expected [200] but found [400]
	at org.testng.Assert.fail(Assert.java:94)
	at org.testng.Assert.failNotEquals(Assert.java:513)
	at org.testng.Assert.assertEqualsImpl(Assert.java:135)
	at org.testng.Assert.assertEquals(Assert.java:116)
	at org.testng.Assert.assertEquals(Assert.java:389)
	at org.testng.Assert.assertEquals(Assert.java:399)
	at AlertAware.api.test.SignIn.logoutCurrentUser(SignIn.java:75)
	at sun.reflect.NativeMethodAccessorImpl.invoke0(Native Method)
	at sun.reflect.NativeMethodAccessorImpl.invoke(NativeMethodAccessorImpl.java:62)
	at sun.reflect.DelegatingMethodAccessorImpl.invoke(DelegatingMethodAccessorImpl.java:43)
	at java.lang.reflect.Method.invoke(Method.java:498)
	at org.testng.internal.MethodInvocationHelper.invokeMethod(MethodInvocationHelper.java:104)
	at org.testng.internal.Invoker.invokeMethod(Invoker.java:645)
	at org.testng.internal.Invoker.invokeTestMethod(Invoker.java:851)
	at org.testng.internal.Invoker.invokeTestMethods(Invoker.java:1177)
	at org.testng.internal.TestMethodWorker.invokeTestMethods(TestMethodWorker.java:129)
	at org.testng.internal.TestMethodWorker.run(TestMethodWorker.java:112)
	at org.testng.TestRunner.privateRun(TestRunner.java:756)
	at org.testng.TestRunner.run(TestRunner.java:610)
	at org.testng.SuiteRunner.runTest(SuiteRunner.java:387)
	at org.testng.SuiteRunner.runSequentially(SuiteRunner.java:382)
	at org.testng.SuiteRunner.privateRun(SuiteRunner.java:340)
	at org.testng.SuiteRunner.run(SuiteRunner.java:289)
	at org.testng.SuiteRunnerWorker.runSuite(SuiteRunnerWorker.java:52)
	at org.testng.SuiteRunnerWorker.run(SuiteRunnerWorker.java:86)
	at org.testng.TestNG.runSuitesSequentially(TestNG.java:1293)
	at org.testng.TestNG.runSuitesLocally(TestNG.java:1218)
	at org.testng.TestNG.runSuites(TestNG.java:1133)
	at org.testng.TestNG.run(TestNG.java:1104)
	at org.testng.remote.AbstractRemoteTestNG.run(AbstractRemoteTestNG.java:132)
	at org.testng.remote.RemoteTestNG.initAndRun(RemoteTestNG.java:236)
	at org.testng.remote.RemoteTestNG.main(RemoteTestNG.java:81)
]]>
    </failure>
  </testcase> <!-- logoutCurrentUser -->
  <testcase name="logoutInvalidUser" time="0.129" classname="AlertAware.api.test.SignIn"/>
  <testcase name="loginAsAUserWithInValidCredentials" time="0.149" classname="AlertAware.api.test.SignIn"/>
  <testcase name="verifyTwoFactorAuthWithInvalidCredentials" classname="AlertAware.api.test.SignIn">
    <skipped/>
  </testcase> <!-- verifyTwoFactorAuthWithInvalidCredentials -->
  <testcase name="get2fa" classname="AlertAware.api.test.SignIn">
    <skipped/>
  </testcase> <!-- get2fa -->
  <testcase name="verifyTwoFactorAuth" classname="AlertAware.api.test.SignIn">
    <skipped/>
  </testcase> <!-- verifyTwoFactorAuth -->
  <testcase name="loginAsAUserWith2fa" classname="AlertAware.api.test.SignIn">
    <skipped/>
  </testcase> <!-- loginAsAUserWith2fa -->
</testsuite> <!-- AlertAware.api.test.SignIn -->
